Workbook

Sheet Проценка
B2: Артикул | C2: Номенклатура | D2: Бренд | E2: Цена | F2: Min Цена | G2: Поставщик | H2: Количество | I2: Уценка согл. | J2: Нов цена-4%
A3: 1 | B3: 9046709050 | C3: Клипса крепления шумоизоляции капота | D3: TOYOTA | E3: 35 | F3: 16 | G3: www.avtoformula.ru | H3: 140 | J3: 35.35 | K3: =J3-E3 -> 0.35 | O3: ТТС Челны УК Склад Центральный склад Челны (осн)
A4: 2 | B4: 3C0853586 | C4: Насадка | D4: VAG | E4: 35 | F4: 10.46 | G4: etp.armtek.ru лег. | H4: 2 | I4: =VLOOKUP(B4,[1]Лист2!$A:$J,10,0) -> 6.895 | J4: 25 | K4: =J4-E4 -> -10 | O4: ТТС Челны УК Склад Центральный склад Челны (осн)
A5: 3 | B5: 3G8853996 3Q7 | C5: Накладка порога кузова задняя правая | D5: VAG | E5: 978 | F5: 1617.22 | G5: autoeuro.ru | H5: 3 | J5: 1552.5312 | K5: =J5-E5 -> 574.5312 | O5: ТТС Челны УК Склад Центральный склад Челны (осн)
A6: 4 | B6: 6Q0810680C | C6: Кронштейн крыла | D6: VAG | E6: 550 | F6: 583 | G6: www.avtoformula.ru | H6: 1 | J6: 559.68 | K6: =J6-E6 -> 9.68 | O6: ТТС Челны УК Склад Центральный склад Челны (осн)
A7: 5 | B7: LR137782 | C7: Кронштейн КреплениЯ Бампера | D7: LANDROVER | E7: 814 | F7: 1418.77 | G7: autoeuro.ru | H7: 3 | J7: 1362.0192 | K7: =J7-E7 -> 548.0192 | O7: ТТС Челны УК Склад Центральный склад Челны (осн)
A8: 6 | B8: 86110F1060 | C8: Стекло лобовое | D8: HYUNDAI/KIA | E8: 59000 | F8: 67450.95 | G8: autoeuro.ru | H8: 10 | J8: 63753 | K8: =J8-E8 -> 4753 | O8: ТТС Челны УК Склад Центральный склад Челны (осн)
A9: 7 | B9: 51119853927 | C9: Решетка переднего бампера | D9: BMW | E9: 18198 | F9: 12787 | G9: www.avtoformula.ru | H9: 1 | I9: =VLOOKUP(B9,[1]Лист2!$A:$J,10,0) -> 13003.97 | J9: 13134.01 | K9: =J9-E9 -> -5063.9903 | O9: ТТС Челны УК Склад Центральный склад Челны (осн)
A10: 8 | B10: 6113320XKV3AA | C10: Накладка стойки двери передней правой | D10: GREAT WALL | E10: 11145 | F10: 7434 | G10: www.avtoformula.ru | H10: 1 | J10: 11256.45 | K10: =J10-E10 -> 111.45 | O10: ТТС Челны УК Склад Центральный склад Челны (осн)
A11: 9 | B11: 61280SJ020 | C11: МОЛДИНГ ДВЕРИ | D11: SUBARU | E11: 6507 | F11: 9326 | G11: www.avtoformula.ru | H11: 1 | I11: =VLOOKUP(B11,[1]Лист2!$A:$J,10,0) -> 4695.495 | J11: 8952.96 | K11: =J11-E11 -> 2445.96 | O11: ТТС Челны УК Склад Центральный склад Челны (осн)
A12: 10 | B12: 638A06958R | C12: Проставка крыло-стойка пер прав | D12: RENAULT | E12: 2352 | F12: 565 | G12: www.avtoformula.ru | H12: 1 | I12: =VLOOKUP(B12,[1]Лист2!$A:$J,10,0) -> 1226.325 | J12: 1238.5883 | K12: =J12-E12 -> -1113.4117 | O12: ТТС Челны УК Склад Центральный склад Челны (осн)
A13: 11 | B13: 86110D7060 | C13: Стекло лобовое | D13: HYUNDAI/KIA | E13: 52000 | F13: 33587 | G13: www.avtoformula.ru | H13: 1 | I13: =VLOOKUP(B13,[1]Лист2!$A:$J,10,0) -> 42509.645 | J13: 42934.741 | K13: =J13-E13 -> -9065.2586 | O13: ТТС Челны УК Склад Центральный склад Челны (осн)
A14: 12 | B14: 86111C5AL0 | C14: Стекло ветровое | D14: HYUNDAI/KIA | E14: 130000 | F14: 110535.23 | G14: autoeuro.ru | H14: 3 | I14: =VLOOKUP(B14,[1]Лист2!$A:$J,10,0) -> 103587.52 | J14: 106113.82 | K14: =J14-E14 -> -23886.179 | O14: ТТС Челны УК Склад Центральный склад Челны (осн)
A15: 13 | B15: 87722N9000CA | C15: Молдинг передней правой двери нижний | D15: HYUNDAI/KIA | E15: 7162 | F15: 5137 | G15: www.avtoformula.ru | H15: 1 | J15: 7233.62 | K15: =J15-E15 -> 71.62 | O15: ТТС Челны УК Склад Центральный склад Челны (осн)
A16: 14 | B16: S203F2713011000 | C16: Бампер передний, нижняя часть | D16: CHANGAN | E16: 14302 | F16: 2131 | G16: www.avtoformula.ru | H16: 1 | J16: 14445.02 | K16: =J16-E16 -> 143.02 | O16: ТТС Челны УК Склад Центральный склад Челны (осн)
A17: 15 | B17: 265855178R | C17: Фонарь противотуманный задний левый | D17: RENAULT | E17: 1263 | F17: 2026 | G17: www.avtoformula.ru | H17: 16 | I17: =VLOOKUP(B17,[1]Лист2!$A:$J,10,0) -> 2448.71 | J17: 2473.1971 | K17: =J17-E17 -> 1210.1971 | O17: ТТС Челны УК Склад Центральный склад Челны (осн)
A18: 16 | B18: 265855178R | C18: Фонарь противотуманный задний левый | D18: RENAULT | E18: 3874 | F18: 2026 | G18: www.avtoformula.ru | H18: 7 | I18: =VLOOKUP(B18,[1]Лист2!$A:$J,10,0) -> 2448.71 | J18: 2473.1971 | K18: =J18-E18 -> -1400.8029 | O18: ТТС Челны УК Склад Центральный склад Челны (осн)
A19: 17 | B19: 5202302170 | C19: УСИЛИТЕЛЬ БАМПЕРА | D19: TOYOTA | E19: 9699 | F19: 9140 | G19: www.avtoformula.ru | H19: 1 | J19: 9795.99 | K19: =J19-E19 -> 96.99 | O19: ТТС Челны УК Склад Центральный склад Челны (осн)
A20: 18 | B20: 565807393 | C20: Кронштейн лев. | D20: VAG | E20: 1029 | F20: 1373 | G20: www.avtoformula.ru | H20: 1 | J20: 1318.08 | K20: =J20-E20 -> 289.08 | O20: ТТС Челны УК Склад Центральный склад Челны (осн)
A21: 19 | B21: 565807394 | C21: Направляющий профиль | D21: VAG | E21: 1035 | F21: 1373 | G21: www.avtoformula.ru | H21: 3 | J21: 1318.08 | K21: =J21-E21 -> 283.08 | O21: ТТС Челны УК Склад Центральный склад Челны (осн)
A22: 20 | B22: 565807394B | C22: Направляющий профиль Задний фонарь D - 23.01.2017>> | D22: VAG | E22: 1031 | F22: 1395 | G22: www.avtoformula.ru | H22: 4 | J22: 1339.2 | K22: =J22-E22 -> 308.2 | O22: ТТС Челны УК Склад Центральный склад Челны (осн)
A23: 21 | B23: 62280SG021 | C23: Молдинг двери задний правый | D23: SUBARU | E23: 3731 | F23: 9086 | G23: www.avtoformula.ru | H23: 1 | J23: 4850 | K23: =J23-E23 -> 1119 | O23: ТТС Челны УК Склад Центральный склад Челны (осн)
A24: 22 | B24: 7816AGNHMVWZ6TFYG | C24: Стекло лобовое Skoda Octavia A7 | D24: FYG | E24: 12894 | F24: 12894 | H24: 1 | J24: 13022.94 | K24: =J24-E24 -> 128.94 | O24: ТТС Челны УК Склад Центральный склад Челны (осн)
A25: 23 | B25: 7P6854661D 041 | C25: Pешетка радиатора | D25: VAG | E25: 13887 | F25: 14759 | G25: www.avtoformula.ru | H25: 1 | J25: 14168.64 | K25: =J25-E25 -> 281.64 | O25: ТТС Челны УК Склад Центральный склад Челны (осн)
A26: 24 | B26: LR058484 | C26: Накладка задней левой двери | D26: LANDROVER | E26: 3011 | F26: 3011 | H26: 1 | J26: 3041.11 | K26: =J26-E26 -> 30.11 | O26: ТТС Челны УК Склад Центральный склад Челны (осн)
A27: 25 | B27: LR061729 | C27: Наружная арка зад. левая | D27: LANDROVER | E27: 22197 | F27: 1937 | G27: www.avtoformula.ru | H27: 1 | I27: =VLOOKUP(B27,[1]Лист2!$A:$J,10,0) -> 2923.48 | J27: 10589 | K27: =J27-E27 -> -11608 | O27: ТТС Челны УК Склад Центральный склад Челны (осн)
A28: 26 | B28: LR086060 | C28: Лобовое стекло с обогревом | D28: LANDROVER | E28: 62461 | F28: 91713 | G28: www.avtoformula.ru | H28: 1 | J28: 75500 | K28: =J28-E28 -> 13039 | O28: ТТС Челны УК Склад Центральный склад Челны (осн)
A29: 27 | B29: LR099300 | C29: Боковая решетка бампера RH | D29: LANDROVER | E29: 11846 | F29: 19314.41 | G29: autoeuro.ru | H29: 1 | J29: 14520 | K29: =J29-E29 -> 2674 | O29: ТТС Челны УК Склад Центральный склад Челны (осн)
A30: 28 | B30: LR099329 | C30: Крышка Форсунки Омывателя ЛЕВАЯ | D30: LANDROVER | E30: 1135 | F30: 1787 | G30: www.avtoformula.ru | H30: 2 | J30: 1715.52 | K30: =J30-E30 -> 580.52 | O30: ТТС Челны УК Склад Центральный склад Челны (осн)
A31: 29 | B31: LR100545 | C31: Переднее левое крыло | D31: LANDROVER | E31: 39967 | F31: 39967 | H31: 2 | J31: 40366.67 | K31: =J31-E31 -> 399.67 | O31: ТТС Челны УК Склад Центральный склад Челны (осн)
A32: 30 | B32: LR117396 | C32: Верхн. кронштейн крепления бампера | D32: LANDROVER | E32: 5955 | F32: 9698.43 | G32: autoeuro.ru | H32: 2 | J32: 6950 | K32: =J32-E32 -> 995 | O32: ТТС Челны УК Склад Центральный склад Челны (осн)
A33: 31 | B33: LR148258 | C33: ЛОКЕР КОЛЕСНОЙ АРКИ | D33: LANDROVER | E33: 10055 | F33: 28817 | G33: www.avtoformula.ru | H33: 3 | J33: 27664.32 | K33: =J33-E33 -> 17609.32 | O33: ТТС Челны УК Склад Центральный склад Челны (осн)
A34: 32 | B34: TK4851W60F | C34: НАКЛАДКА ПЛАСТИКОВАЯ КОЛЕСНОЙ АРКИ CX-9'2017/18 | D34: Mazda | E34: 19257 | F34: 8535 | G34: www.avtoformula.ru | H34: 1 | J34: 19449.57 | K34: =J34-E34 -> 192.57 | O34: ТТС Челны УК Склад Центральный склад Челны (осн)
A35: 33 | B35: 11180840339500 | C35: Усилитель брызговика левый | D35: LADA | E35: 783 | F35: 648 | G35: www.avtoformula.ru | H35: 1 | J35: 790.83 | K35: =J35-E35 -> 7.83 | O35: УКТТС Казань Склад Центральный склад Казань (осн) Тихорецкая
A36: 34 | B36: 2803720U2400 | C36: Кронштейн бампера правый | D36: JAC | E36: 341 | F36: 236 | G36: www.avtoformula.ru | H36: 1 | J36: 344.41 | K36: =J36-E36 -> 3.41 | O36: УКТТС Казань Склад Центральный склад Казань (осн) Тихорецкая
A37: 35 | B37: 5022035800 | C37: Уплотнитель панели воздухозаборника | D37: GEELY | E37: 1038 | F37: 363 | G37: www.avtoformula.ru | H37: 1 | J37: 1048.38 | K37: =J37-E37 -> 10.38 | O37: УКТТС Казань Склад Центральный склад Казань (осн) Тихорецкая
A38: 36 | B38: 602000037AA | C38: БРЫЗГОВИК ЗАДНИЙ ЛЕВЫЙ T18/T1A/T1D | D38: LANDROVER | E38: 310 | F38: 389 | G38: www.avtoformula.ru | H38: 1 | J38: 373.44 | K38: =J38-E38 -> 63.44 | O38: УКТТС Казань Склад Центральный склад Казань (осн) Тихорецкая
A39: 37 | B39: 8200700969 | C39: Фиксатор переднего бампера | D39: RENAULT | E39: 158 | F39: 33.82 | G39: etp.armtek.ru лег. | H39: 4 | J39: 159.58 | K39: =J39-E39 -> 1.58 | O39: УКТТС Казань Склад Центральный склад Казань (осн) Тихорецкая
A40: 38 | B40: 8450007743 | C40: Ручка передней двери внутренняя правая в сборе | D40: LADA | E40: 396 | F40: 246 | G40: www.avtoformula.ru | H40: 1 | J40: 399.96 | K40: =J40-E40 -> 3.96 | O40: УКТТС Казань Склад Центральный склад Казань (осн) Тихорецкая
A41: 39 | B41: 9046709050 | C41: Клипса крепления шумоизоляции капота | D41: TOYOTA | E41: 35 | F41: 16 | G41: www.avtoformula.ru | H41: 20 | J41: 35.35 | K41: =J41-E41 -> 0.35 | O41: УКТТС Казань Склад Центральный склад Казань (осн) Тихорецкая
...
